thread 'main' panicked at 'assertion failed: r.is_err()', ui/numbers-arithmetic/next-power-of-two-overflow-debug.rs:22:5
note: run with `RUST_BACKTRACE=1` environment variable to display a backtrace
